Workbook

Sheet README
B2: Analytical Study of Ankita Cashew Processing
B3: BDM Capstone — FINAL Analysis Workbook (native Excel charts)
B4: Akash Jana | Roll 23f2000990 | IIT Madras BS Degree
B6: All charts here are native Excel charts (editable; right-click > Edit Data).
B7: Reproduced by analysis_final.py.
B9: Sheets: Cleaning Log, Transactions, Descriptive Stats, Annual Summary, Forecast, Yield,
B10: P&L Model (live formulas), Sensitivity (colour scale), Buyer Risk Model, Buyer Tiers,
B11: Anomalies. Blue = inputs/assumptions, black = formulas. ₹ amounts, KG weights.

Sheet Cleaning Log
A1: Data Cleaning Log
A3: Step | B3: Count
A4: Cells scanned | B4: 5572
A5: Non-data rows skipped | B5: 4720
A6: Exact duplicates removed | B6: 2
A7: Clean transactions kept | B7: 850
A9: Duplicate examples: ₹70,000 cash sale (Ankita 31-Mar-2023); ₹25,00,000 RCN purchase (Ankita 30-Jul-2024).

Sheet Transactions
A1: Company | B1: Flow | C1: Goods | D1: Date | E1: Counterparty | F1: Amount (₹) | G1: Financial Year
A2: Adrita | B2: Sale | C2: FCN | D2: 44671 | E2: M/s Shree Taran Traders | F2: 243628 | G2: FY22-23
A3: Adrita | B3: Sale | C3: FCN | D3: 44677 | E3: ASHWANI KUMAR NEEL KAMAL | F3: 526073 | G3: FY22-23
A4: Adrita | B4: Purchase | C4: RCN | D4: 44688 | E4: VIJAY TRADERS | F4: 1683200 | G4: FY22-23
A5: Adrita | B5: Sale | C5: FCN | D5: 44698 | E5: M/S RADHYSHYAM SAMBHUNATH | F5: 302860 | G5: FY22-23
A6: Adrita | B6: Sale | C6: FCN | D6: 44705 | E6: M/S PADAM & SONS | F6: 980712 | G6: FY22-23
A7: Adrita | B7: Purchase | C7: RCN | D7: 44710 | E7: Maa Laxmi Cashew | F7: 732947.2 | G7: FY22-23
A8: Adrita | B8: Sale | C8: FCN | D8: 44725 | E8: ASHWANI KUMAR NEEL KAMAL | F8: 910585 | G8: FY22-23
A9: Adrita | B9: Purchase | C9: RCN | D9: 44729 | E9: Durga Cashew Co | F9: 552619.05 | G9: FY22-23
A10: Adrita | B10: Sale | C10: FCN | D10: 44734 | E10: Subham Traders | F10: 892778 | G10: FY22-23
A11: Adrita | B11: Purchase | C11: RCN | D11: 44741 | E11: Durga Cashew Co | F11: 490476.19 | G11: FY22-23
A12: Adrita | B12: Purchase | C12: RCN | D12: 44741 | E12: Ankita Cashew Processing | F12: 4000000 | G12: FY22-23
A13: Adrita | B13: Sale | C13: RCN | D13: 44742 | E13: Nandi Cashew Processing | F13: 1718080 | G13: FY22-23
... A851: Ankita | B851: Purchase | C851: RCN | D851: 46057 | E851: Ahana Enterprises | F851: 3981570 | G851: FY25-26

Sheet Descriptive Stats
A1: Descriptive Statistics — all variables
A3: Variable | B3: Count | C3: Mean | D3: Median | E3: SD | F3: Min | G3: Max
A4: Sale amount (₹) | B4: 578 | C4: 514839 | D4: 349333 | E4: 511815 | F4: 10476 | G4: 4000000
A5: Purchase amount (₹) | B5: 272 | C5: 995213 | D5: 565386 | E5: 1082649 | F5: 1907 | G5: 5041701
A6: RCN price (₹/KG) | B6: 79 | C6: 126.5 | D6: 120 | E6: 25.3 | F6: 89 | G6: 179.1
A7: Buyer revenue (₹) | B7: 130 | C7: 2272582 | D7: 893287 | E7: 4303064 | F7: 10476 | G7: 30087807
A8: Buyer orders (count) | B8: 130 | C8: 4.3 | D8: 2 | E8: 6 | F8: 1 | G8: 36
A9: Buyer risk score (0-100) | B9: 130 | C9: 55.7 | D9: 54.8 | E9: 13.6 | F9: 27.8 | G9: 100
A10: Contribution per kg kernel (₹) | B10: 3 | C10: 80.1 | D10: 119.9 | E10: 173.5 | F10: -109.8 | G10: 230.2

Sheet Annual Summary
A1: Annual Sales vs Purchase
A3: Financial Year | B3: Sales (₹) | C3: Purchase (₹) | D3: Net (₹)
A4: FY22-23 | B4: 72524077 | C4: 73780058 | D4: =B4-C4 -> -1255981
A5: FY23-24 | B5: 76227072 | C5: 68141555 | D5: =B5-C5 -> 8085517
A6: FY24-25 | B6: 81086538 | C6: 70636908 | D6: =B6-C6 -> 10449630
A7: FY25-26 | B7: 67738985 | C7: 58139303 | D7: =B7-C7 -> 9599682

Sheet Forecast
A1: Forecast Accuracy (6-month holdout)
A3: Model | B3: RMSE (₹) | C3: MAE (₹)
A4: ARIMA | B4: 2527935 | C4: 2167929
A5: Linear (base) | B5: 2181363 | C5: 1929917
A6: Naive | B6: 4304027 | C6: 3028328

Sheet Yield
A1: Yield per Cycle
A3: Cycle | B3: Yield % | C3: Target % | D3: Variance | E3: Z-score | F3: Outlier
A4: Ad-22-23 | B4: 17.4 | C4: 22 | D4: -4.6 | E4: -0.22 | F4: No
A5: Ad-23-24 | B5: 20.2 | C5: 22 | D5: -1.8 | E5: 0.39 | F5: No
A6: Ad-24-25 | B6: 22.8 | C6: 22 | D6: 0.8 | E6: 0.95 | F6: No
A7: Ad-25-26 | B7: 19.8 | C7: 22 | D7: -2.2 | E7: 0.29 | F7: No
A8: An-22-23 | B8: 10.8 | C8: 22 | D8: -11.2 | E8: -1.66 | F8: Yes
A9: An-23-24 | B9: 17.8 | C9: 22 | D9: -4.2 | E9: -0.16 | F9: No
A10: An-24-25 | B10: 13.9 | C10: 22 | D10: -8.1 | E10: -1 | F10: No
A11: An-25-26 | B11: 25 | C11: 22 | D11: 3 | E11: 1.42 | F11: No

Sheet P&L Model
A1: Profit & Loss — Live Contribution Model
A2: Edit blue assumption cells to test scenarios.
A4: Assumptions
A5: RCN price (₹/kg) | B5: 123.2
A6: Outturn / yield | B6: 0.22
A7: Processing (₹/kg kernel) | B7: 30
A8: Kernel selling price (₹/kg) | B8: 709.8
A10: Computed
A11: RCN cost per kg kernel | B11: =B5/B6 -> 560
A12: Total cost per kg kernel | B12: =B11+B7 -> 590
A13: Contribution per kg kernel | B13: =B8-B12 -> 119.8
A14: Margin % | B14: =B13/B8 -> 0.16877994
A15: Break-even price (₹/kg) | B15: =B12 -> 590
A16: Break-even outturn | B16: =B5/(B8-B7) -> 0.18122977
A18: Profit build-up (₹/kg)
A19: Component | B19: ₹/kg
A20: Selling price | B20: =B8 -> 709.8
A21: RCN cost | B21: =B11 -> 560
A22: Processing | B22: =B7 -> 30
A23: Contribution | B23: =B13 -> 119.8
A26: By grade
A27: Grade | B27: Price (₹/kg) | C27: Contribution (₹/kg)
A28: Whole | B28: 820 | C28: =B28-B12 -> 230
A29: Broken | B29: 480 | C29: =B29-B12 -> -110

Sheet Sensitivity
A1: Contribution Sensitivity (₹/kg kernel)
A2: Rows = RCN price change · Columns = selling-price change · live formulas off 'P&L Model'.
A4: RCN ↓ / Price → | B4: -10% | C4: -5% | D4: +0% | E4: +5% | F4: +10%
A5: -10% | B5: ='P&L Model'!$B$8*(1+-0.1)-('P&L Model'!$B$5*(1+-0.1)/'P&L Model'!$B$6+'P&L Model'!$B$7) -> 104.82 | C5: ='P&L Model'!$B$8*(1+-0.05)-('P&L Model'!$B$5*(1+-0.1)/'P&L Model'!$B$6+'P&L Model'!$B$7) -> 140.31 | D5: ='P&L Model'!$B$8*(1+0)-('P&L Model'!$B$5*(1+-0.1)/'P&L Model'!$B$6+'P&L Model'!$B$7) -> 175.8 | E5: ='P&L Model'!$B$8*(1+0.05)-('P&L Model'!$B$5*(1+-0.1)/'P&L Model'!$B$6+'P&L Model'!$B$7) -> 211.29 | F5: ='P&L Model'!$B$8*(1+0.1)-('P&L Model'!$B$5*(1+-0.1)/'P&L Model'!$B$6+'P&L Model'!$B$7) -> 246.78
A6: -5% | B6: ='P&L Model'!$B$8*(1+-0.1)-('P&L Model'!$B$5*(1+-0.05)/'P&L Model'!$B$6+'P&L Model'!$B$7) -> 76.82 | C6: ='P&L Model'!$B$8*(1+-0.05)-('P&L Model'!$B$5*(1+-0.05)/'P&L Model'!$B$6+'P&L Model'!$B$7) -> 112.31 | D6: ='P&L Model'!$B$8*(1+0)-('P&L Model'!$B$5*(1+-0.05)/'P&L Model'!$B$6+'P&L Model'!$B$7) -> 147.8 | E6: ='P&L Model'!$B$8*(1+0.05)-('P&L Model'!$B$5*(1+-0.05)/'P&L Model'!$B$6+'P&L Model'!$B$7) -> 183.29 | F6: ='P&L Model'!$B$8*(1+0.1)-('P&L Model'!$B$5*(1+-0.05)/'P&L Model'!$B$6+'P&L Model'!$B$7) -> 218.78
A7: +0% | B7: ='P&L Model'!$B$8*(1+-0.1)-('P&L Model'!$B$5*(1+0)/'P&L Model'!$B$6+'P&L Model'!$B$7) -> 48.82 | C7: ='P&L Model'!$B$8*(1+-0.05)-('P&L Model'!$B$5*(1+0)/'P&L Model'!$B$6+'P&L Model'!$B$7) -> 84.31 | D7: ='P&L Model'!$B$8*(1+0)-('P&L Model'!$B$5*(1+0)/'P&L Model'!$B$6+'P&L Model'!$B$7) -> 119.8 | E7: ='P&L Model'!$B$8*(1+0.05)-('P&L Model'!$B$5*(1+0)/'P&L Model'!$B$6+'P&L Model'!$B$7) -> 155.29 | F7: ='P&L Model'!$B$8*(1+0.1)-('P&L Model'!$B$5*(1+0)/'P&L Model'!$B$6+'P&L Model'!$B$7) -> 190.78
A8: +5% | B8: ='P&L Model'!$B$8*(1+-0.1)-('P&L Model'!$B$5*(1+0.05)/'P&L Model'!$B$6+'P&L Model'!$B$7) -> 20.82 | C8: ='P&L Model'!$B$8*(1+-0.05)-('P&L Model'!$B$5*(1+0.05)/'P&L Model'!$B$6+'P&L Model'!$B$7) -> 56.31 | D8: ='P&L Model'!$B$8*(1+0)-('P&L Model'!$B$5*(1+0.05)/'P&L Model'!$B$6+'P&L Model'!$B$7) -> 91.8 | E8: ='P&L Model'!$B$8*(1+0.05)-('P&L Model'!$B$5*(1+0.05)/'P&L Model'!$B$6+'P&L Model'!$B$7) -> 127.29 | F8: ='P&L Model'!$B$8*(1+0.1)-('P&L Model'!$B$5*(1+0.05)/'P&L Model'!$B$6+'P&L Model'!$B$7) -> 162.78
A9: +10% | B9: ='P&L Model'!$B$8*(1+-0.1)-('P&L Model'!$B$5*(1+0.1)/'P&L Model'!$B$6+'P&L Model'!$B$7) -> -7.18 | C9: ='P&L Model'!$B$8*(1+-0.05)-('P&L Model'!$B$5*(1+0.1)/'P&L Model'!$B$6+'P&L Model'!$B$7) -> 28.31 | D9: ='P&L Model'!$B$8*(1+0)-('P&L Model'!$B$5*(1+0.1)/'P&L Model'!$B$6+'P&L Model'!$B$7) -> 63.8 | E9: ='P&L Model'!$B$8*(1+0.05)-('P&L Model'!$B$5*(1+0.1)/'P&L Model'!$B$6+'P&L Model'!$B$7) -> 99.29 | F9: ='P&L Model'!$B$8*(1+0.1)-('P&L Model'!$B$5*(1+0.1)/'P&L Model'!$B$6+'P&L Model'!$B$7) -> 134.78

Sheet Buyer Risk Model
A1: Buyer Risk Model
A2: Risk score 0-100 from recency, frequency, tenure and exposure. Tier sets credit limit. | L2: Illustrative logistic model: AUC=0.96, accuracy=0.923 (simulated delays).
L4: Recency | M4: Low | N4: Medium | O4: High
A5: ASHWANI KUMAR NEEL KAMAL | B5: 30087807 | C5: 26 | D5: 1157223 | E5: 18 | F5: 1368 | G5: 23 | H5: 29.6 | I5: Low | J5: 2616000 | L5: 18 | M5: 30087807
A6: Maa Laxmi Cashew Processing | B6: 24082072 | C6: 13 | D6: 1852467 | E6: 470 | F6: 892 | G6: 11 | H6: 51.4 | I6: Medium | J6: 2189000 | L6: 470 | N6: 24082072
A7: M/s Ashwani Kumar Neel Kamal | B7: 20570081 | C7: 19 | D7: 1082636 | E7: 83 | F7: 1322 | G7: 16 | H7: 30.9 | I7: Low | J7: 2571000 | L7: 83 | M7: 20570081
A8: DEVIDEEN HANUMANPRASAD | B8: 17125429 | C8: 33 | D8: 518952 | E8: 45 | F8: 833 | G8: 23 | H8: 31.1 | I8: Low | J8: 1489000 | L8: 45 | M8: 17125429
A9: Satyam Traders | B9: 10391863 | C9: 16 | D9: 649491 | E9: 524 | F9: 662 | G9: 10 | H9: 44.9 | I9: Medium | J9: 1039000 | L9: 524 | N9: 10391863
A10: Nandi Cashew Processing | B10: 10064274 | C10: 7 | D10: 1437753 | E10: 615 | F10: 706 | G10: 7 | H10: 58.1 | I10: Medium | J10: 1438000 | L10: 615 | N10: 10064274
A11: Shree Taran Traders | B11: 7999480 | C11: 36 | D11: 222208 | E11: 301 | F11: 1007 | G11: 26 | H11: 34.5 | I11: Medium | J11: 308000 | L11: 301 | N11: 7999480
A12: P P Enterprises | B12: 7725387 | C12: 26 | D12: 297130 | E12: 208 | F12: 1094 | G12: 18 | H12: 30.4 | I12: Low | J12: 858000 | L12: 208 | M12: 7725387
A13: Sashwat Traders | B13: 7561262 | C13: 11 | D13: 687387 | E13: 497 | F13: 805 | G13: 8 | H13: 45.1 | I13: Medium | J13: 945000 | L13: 497 | N13: 7561262
A14: Ramesh Chand Naresh Kumar | B14: 7119041 | C14: 22 | D14: 323593 | E14: 31 | F14: 621 | G14: 12 | H14: 27.9 | I14: Low | J14: 1187000 | L14: 31 | M14: 7119041
A15: DEB TRADERS | B15: 5692491 | C15: 6 | D15: 948748 | E15: 222 | F15: 827 | G15: 6 | H15: 43.5 | I15: Medium | J15: 949000 | L15: 222 | N15: 5692491
A16: M/s Devideen Hanuman Prasad | B16: 5687173 | C16: 13 | D16: 437475 | E16: 389 | F16: 546 | G16: 9 | H16: 43.9 | I16: Medium | J16: 632000 | L16: 389 | N16: 5687173
A17: M/s Satyam Traders | B17: 5079971 | C17: 8 | D17: 634996 | E17: 194 | F17: 848 | G17: 7 | H17: 39.1 | I17: Medium | J17: 726000 | L17: 194 | N17: 5079971
A18: P P ENTERPRISE | B18: 4956847 | C18: 8 | D18: 619606 | E18: 167 | F18: 912 | G18: 7 | H18: 37.4 | I18: Medium | J18: 708000 | L18: 167 | N18: 4956847
A19: M/s Nandi Cashew Processing | B19: 4715780 | C19: 3 | D19: 1571927 | E19: 1175 | F19: 187 | G19: 3 | H19: 81.2 | I19: High | J19: 629000 | L19: 1175 | O19: 4715780
A20: SHRI KRISHNA CASHEW PROCESSING | B20: 4340633 | C20: 8 | D20: 542579 | E20: 470 | F20: 729 | G20: 6 | H20: 45.3 | I20: Medium | J20: 723000 | L20: 470 | N20: 4340633
A21: BLPD NUTS PVT LTD | B21: 4280216 | C21: 3 | D21: 1426739 | E21: 307 | F21: 98 | G21: 2 | H21: 52.6 | I21: Medium | J21: 2140000 | L21: 307 | N21: 4280216
A22: Adrita Cashew Processing | B22: 4000000 | C22: 1 | D22: 4000000 | E22: 1322 | F22: 1 | G22: 1 | H22: 100 | I22: High | J22: 1600000 | L22: 1322 | O22: 4000000
A23: Keshav Trading Co | B23: 3890169 | C23: 10 | D23: 389017 | E23: 25 | F23: 368 | G23: 8 | H23: 39.1 | I23: Medium | J23: 486000 | L23: 25 | N23: 3890169
A24: Radhyshyam Sambhu Nath | B24: 3765149 | C24: 7 | D24: 537878 | E24: 987 | F24: 346 | G24: 6 | H24: 66.6 | I24: High | J24: 251000 | L24: 987 | O24: 3765149
A25: M/S DEV TRADERS | B25: 3723680 | C25: 4 | D25: 930920 | E25: 20 | F25: 309 | G25: 4 | H25: 45.6 | I25: Medium | J25: 931000 | L25: 20 | N25: 3723680
A26: M/S SHRI SHYAM TRADERS | B26: 3682004 | C26: 8 | D26: 460250 | E26: 90 | F26: 72 | G26: 3 | H26: 27.8 | I26: Low | J26: 2455000 | L26: 90 | M26: 3682004
A27: Manni Lal Madhav Saran | B27: 3399278 | C27: 5 | D27: 679856 | E27: 643 | F27: 625 | G27: 5 | H27: 56.2 | I27: Medium | J27: 680000 | L27: 643 | N27: 3399278
A28: SALASAR BHANDER | B28: 3308138 | C28: 5 | D28: 661628 | E28: 61 | F28: 462 | G28: 4 | H28: 40 | I28: Medium | J28: 827000 | L28: 61 | N28: 3308138
A29: Padam & Sons | B29: 3019911 | C29: 4 | D29: 754978 | E29: 525 | F29: 573 | G29: 4 | H29: 54.3 | I29: Medium | J29: 755000 | L29: 525 | N29: 3019911
A30: Swarnali Cashew Processing | B30: 2989434 | C30: 5 | D30: 597887 | E30: 358 | F30: 841 | G30: 5 | H30: 45.1 | I30: Medium | J30: 598000 | L30: 358 | N30: 2989434
A31: Swarna Shri Cashew | B31: 2791234 | C31: 6 | D31: 465206 | E31: 406 | F31: 139 | G31: 5 | H31: 53.5 | I31: Medium | J31: 558000 | L31: 406 | N31: 2791234
A32: M/S PADAM & SONS | B32: 2746502 | C32: 4 | D32: 686626 | E32: 937 | F32: 421 | G32: 4 | H32: 67.1 | I32: High | J32: 275000 | L32: 937 | O32: 2746502
A33: SHREE TRADERS | B33: 2571234 | C33: 9 | D33: 285693 | E33: 712 | F33: 210 | G33: 7 | H33: 58.6 | I33: Medium | J33: 367000 | L33: 712 | N33: 2571234
A34: ARJU CASHEW PROCESSING | B34: 2506250 | C34: 1 | D34: 2506250 | E34: 545 | F34: 1 | G34: 1 | H34: 71.9 | I34: High | J34: 1002000 | L34: 545 | O34: 2506250
A35: SALONI TRADERS | B35: 2321650 | C35: 10 | D35: 232165 | E35: 333 | F35: 592 | G35: 9 | H35: 44.9 | I35: Medium | J35: 258000 | L35: 333 | N35: 2321650
A36: M/s Sree Krishna Cashew Processing | B36: 2298920 | C36: 3 | D36: 766307 | E36: 1171 | F36: 191 | G36: 3 | H36: 77 | I36: High | J36: 307000 | L36: 1171 | O36: 2298920
A37: M/s Mahesh Cashew Processing | B37: 2260040 | C37: 5 | D37: 452008 | E37: 1051 | F37: 311 | G37: 5 | H37: 70.5 | I37: High | J37: 181000 | L37: 1051 | O37: 2260040
A38: M/S BERA CASHEW PROCESSING(Goutam) | B38: 2220017 | C38: 1 | D38: 2220017 | E38: 322 | F38: 1 | G38: 1 | H38: 64.6 | I38: Medium | J38: 2220000 | L38: 322 | N38: 2220017
A39: Maa Sitala Cashew Trading & Processing | B39: 2095254 | C39: 4 | D39: 523814 | E39: 375 | F39: 741 | G39: 4 | H39: 46.7 | I39: Medium | J39: 524000 | L39: 375 | N39: 2095254
A40: GUPTA STORE | B40: 2042548 | C40: 10 | D40: 204255 | E40: 500 | F40: 261 | G40: 6 | H40: 47.1 | I40: Medium | J40: 340000 | L40: 500 | N40: 2042548
A41: M/s Shree Taran Traders | B41: 2040553 | C41: 9 | D41: 226728 | E41: 1062 | F41: 330 | G41: 7 | H41: 65.8 | I41: Medium | J41: 292000 | L41: 1062 | N41: 2040553
...

Sheet Buyer Tiers
A1: Buyer Tiers & Credit Exposure
A3: Tier | B3: Buyers | C3: Credit exposure (₹)
A4: Low | B4: 7 | C4: 14125000
A5: Medium | B5: 90 | C5: 44005000
A6: High | B6: 33 | C6: 8961000

Sheet Anomalies
A1: Anomaly Detection
A3: Flagged 29 of 850 (3.4%): 12 Z-score, 17 Isolation Forest. 3 months flagged by reconciliation.
A5: Date | B5: Company | C5: Flow | D5: Goods | E5: Party | F5: Amount (₹) | G5: Z | H5: Flagged by | J5: Idx | K5: Normal | L5: Anomaly | N5: Month | O5: Kernel/ RCN ratio
A6: 2022-11-19 | B6: Ankita | C6: Purchase | D6: RCN | E6: New Kumudini Radio | F6: 1907 | G6: -0.92 | H6: Isolation Forest | J6: 1 | K6: 1718080 | N6: 2022-04 | O6: 0.041
A7: 2023-11-03 | B7: Adrita | C7: Purchase | D7: RCN | E7: SUNRICE CHEMICALS PVT LT | F7: 20861 | G7: -1.03 | H7: Isolation Forest | J7: 2 | K7: 1771500 | N7: 2022-05 | O7: 0.122
A8: 2023-03-29 | B8: Ankita | C8: Purchase | D8: RCN | E8: SUNRICE CHEMICALS PVT LT | F8: 3035 | G8: -0.91 | H8: Isolation Forest | J8: 3 | K8: 251448 | N8: 2022-06 | O8: 0.038
A9: 2023-02-06 | B9: Ankita | C9: Purchase | D9: RCN | E9: D K Day & Sarker & Co | F9: 10000 | G9: -0.91 | H9: Isolation Forest | J9: 4 | K9: 285600 | N9: 2022-07 | O9: 0.139
A10: 2024-04-15 | B10: Ankita | C10: Purchase | D10: FCN | E10: SUSHMA INDUSTRIES | F10: 43000 | G10: -1.38 | H10: Isolation Forest | J10: 5 | K10: 285714 | N10: 2022-08 | O10: 0.178
A11: 2023-09-03 | B11: Ankita | C11: Purchase | D11: FCN | E11: DEVI CASHEW PROCESSING | F11: 47619 | G11: -1.37 | H11: Isolation Forest | J11: 6 | K11: 459050 | N11: 2022-09 | O11: 0.328
A12: 2025-09-22 | B12: Adrita | C12: Purchase | D12: FCN | E12: MAA CHANDI CASHEW NUT PR | F12: 51900 | G12: -1.2 | H12: Isolation Forest | J12: 7 | K12: 666667 | N12: 2022-10 | O12: 0.045
A13: 2023-12-01 | B13: Ankita | C13: Sale | D13: RCN | E13: Maa Laxmi Cashew Process | F13: 3021429 | G13: 2.39 | H13: Isolation Forest | J13: 8 | K13: 95240 | N13: 2022-11 | O13: 0.271
A14: 2023-12-09 | B14: Ankita | C14: Sale | D14: FCN | E14: CHANDAN PURAKAYATWA | F14: 14286 | G14: -1.01 | H14: Isolation Forest | J14: 9 | K14: 488800 | N14: 2022-12 | O14: 0.328
A15: 2023-05-05 | B15: Adrita | C15: Purchase | D15: RCN | E15: SUNRICE CHEMICALS PVT LT | F15: 17524 | G15: -1.03 | H15: Isolation Forest | J15: 10 | K15: 216000 | N15: 2023-01 | O15: 0.244
A16: 2022-05-10 | B16: Ankita | C16: Purchase | D16: RCN | E16: CHAKADOLA POLYMERS PVT L | F16: 14578 | G16: -0.91 | H16: Isolation Forest | J16: 11 | K16: 380950 | N16: 2023-02 | O16: 0.482
A17: 2025-12-29 | B17: Adrita | C17: Purchase | D17: FCN | E17: Shoel Cashew Processing | F17: 285714 | G17: -0.54 | H17: Isolation Forest | J17: 12 | K17: 152381 | N17: 2023-03 | O17: 0.157
J18: 13 | K18: 252000 | N18: 2023-04 | O18: 0.087
J19: 14 | L19: 2275520 | N19: 2023-05 | O19: 0.25
J20: 15 | K20: 936000 | N20: 2023-06 | O20: 0.823
J21: 16 | K21: 1523500 | N21: 2023-07 | O21: 0.119
J22: 17 | K22: 205500 | N22: 2023-08 | O22: 0.182
J23: 18 | K23: 1580950 | N23: 2023-09 | O23: 0.51
J24: 19 | K24: 1092000 | N24: 2023-10 | O24: 0.312
J25: 20 | K25: 2142857 | N25: 2023-11 | O25: 0.179
J26: 21 | K26: 423810 | N26: 2023-12 | O26: 0.371
J27: 22 | K27: 238096 | N27: 2024-01 | O27: 0.116
J28: 23 | K28: 952381 | N28: 2024-02 | O28: 0.24
J29: 24 | K29: 285715 | N29: 2024-03 | O29: 0.196
J30: 25 | K30: 481219 | N30: 2024-04 | O30: 0.092
J31: 26 | K31: 131690 | N31: 2024-05 | O31: 0.106
... J50: 45 | K50: 235144 | N50: 2026-02 | O50: 0.03
J51: 46 | K51: 306890
J52: 47 | K52: 918134
J53: 48 | K53: 904482
J54: 49 | K54: 269331
J55: 50 | K55: 885772
J56: 51 | K56: 109000
J57: 52 | K57: 172380
J58: 53 | K58: 360038
J59: 54 | K59: 877606
J60: 55 | K60: 117047
...
